Workbook

Sheet Funds for BILLS 
A1: Paid and Pending Bills as on 07/09/2026 – MahaSTRIDE Operation | M1: 3451A215 | O1: 3451A224 | Q1: 3451A233
A2: Sr.No. | B2: Particulars | C2: Invoice No. | D2: Date | E2: Billing Month | F2: Bills amount Rs | G2: Status | H2: Bills-Paid | I2: Panding Bill amount | K2: Order Date | L2: Remarks, if any | M2: 10 Cont Services | N2: 26 Advertise | O2: 10 Cont Services | P2: 26 Advertise | Q2: 06 Telephone | R2: 10 Cont Services | S2: 13 Office Exp | T2: 14 Rent | U2: 17 Computer | V2: 26 Advertise | W2: 27 Minor Works | X2: 28 Prof Services | Y2: 31 Graint in Aid
A3: 1 | B3: PMC - KPMG Advisory Ser | C3: KASP-MH/100069 | D3: 25/05/2026 | E3: 10% Deliverable | F3: 3657952 | G3: Committee Approved 05.08.2026 | I3: =F3 -> 3657952 | J3: =F3-H3-I3 -> 0 | O3: =H3 -> 0
B4: PMC - KPMG Advisory Ser | C4: KASP-MH/A100127 | D4: 46184 | E4: NOV. 2025 | F4: 970255 | G4: 970255 | H4: 970255 | J4: =F4-H4-I4 -> 0 | K4: 15.07.2026 | M4: =H4 -> 970255
A5: 2 | B5: DSU Nashik KPMG | C5: KASP-HR/A100169 | D5: 46160 | E5: 46023 | F5: 4633825 | G5: Issued | H5: 4633825 | J5: =F5-H5-I5 -> 0 | K5: 22.07.2026 | L5: Substitution of the staff has been approved by IBRD/World Bank, and the contract amendment is in process. | O5: =H5 -> 4633825
B6: DSU Nashik KPMG | C6: KASP-HR/A100228 | D6: 31/05/2026 | E6: 46054 | F6: 5067348 | G6: Issued | H6: 5067348 | J6: =F6-H6-I6 -> 0 | K6: 22.07.2026 | O6: =H6 -> 5067348
B7: DSU Nashik KPMG | C7: KASP-HR/A100218 | D7: 31/05/2026 | E7: 46082 | F7: 5158115 | G7: Issued | H7: 5158115 | J7: =F7-H7-I7 -> 0 | K7: 22.07.2026 | O7: =H7 -> 5158115
B8: DSU Nashik KPMG | C8: KASP-HR/A100345 | D8: 29/06/2026 | E8: 46113 | F8: 5334952 | G8: Committee Approved 05.08.2026 | I8: =F8 -> 5334952 | J8: =F8-H8-I8 -> 0 | O8: {=H8:M8} -> 0 | P8: 5334952 | Q8: 0 | R8: 0 | S8: 0 | T8: 0
B9: DSU Nashik KPMG | C9: KASP-HR/A100536 | D9: 30/07/2026 | E9: 46143 | F9: 5175888 | G9: Received 10.08.2026 | I9: =F9 -> 5175888 | J9: =F9-H9-I9 -> 0 | O9: =F9 -> 5175888
B10: DSU Nashik KPMG | C10: KASP-HR/A100566 | D10: 30/07/2026 | E10: 46174 | F10: 5087025 | G10: Received 10.08.2026 | I10: =F10 -> 5087025 | J10: =F10-H10-I10 -> 0 | O10: =F10 -> 5087025
B11: DSU Nashik KPMG | C11: KASP-HR/A100611 | D11: 46247 | E11: Incecption Report | F11: 3431999 | G11: Received Tax invoice 18.08.2026 | I11: =F11 -> 3431999 | J11: =F11-H11-I11 -> 0 | M11: =F11 -> 3431999
B12: DSU Nashik KPMG | C12: KASP-HR/A100616 | D12: 46248 | E12: Private Capital Mobi | F12: 4290000 | G12: Received Tax invoice 18.08.2026 | I12: =F12 -> 4290000 | J12: =F12-H12-I12 -> 0 | M12: =F12 -> 4290000
B13: DSU Nashik KPMG | C13: KASP-HR/A100627 | D13: 46252 | E13: Public Disclosure | F13: 10296000 | G13: Received Tax invoice 18.08.2026 | I13: =F13 -> 10296000 | J13: =F13-H13-I13 -> 0 | M13: =F13 -> 10296000
A14: 3 | B14: DSU Pune - STC | C14: MahaSTRIDE/DSU/Pune/005 | D14: 46099 | E14: Oct.2025 | F14: 2512984 | G14: Issued | H14: 2512984 | J14: =F14-H14-I14 -> 0 | K14: 21.07.2026 | L14: Substitution of the staff has been approved by IBRD/World Bank, and the contract amendment is in process. | M14: =F14 -> 2512984
B15: DSU Pune - STC | C15: MahaSTRIDE/DSU/Pune/006 | D15: 46099 | E15: Nov.2025 | F15: 2760750 | G15: Issued | H15: 2760750 | J15: =F15-H15-I15 -> 0 | K15: 21.07.2026 | M15: =F15 -> 2760750
B16: DSU Pune - STC | C16: MahaSTRIDE/DSU/Pune/007 | D16: 46099 | E16: Dec.2025 | F16: 2681371 | G16: Issued | H16: 2681371 | J16: =F16-H16-I16 -> 0 | K16: 21.07.2026 | M16: =F16 -> 2681371
B17: DSU Pune - STC | C17: MahaSTRIDE/8 | D17: 46150 | E17: 46023 | F17: 2610484 | G17: aproved 08.07.2026 File Submited | I17: =F17 -> 2610484 | J17: =F17-H17-I17 -> 0 | M17: =H17 -> 0
B18: DSU Pune - STC | C18: MahaSTRIDE/9 | D18: 46150 | E18: 46054 | F18: 2475000 | G18: aproved 08.07.2026 File Submited | I18: =F18 -> 2475000 | J18: =F18-H18-I18 -> 0 | M18: =H18 -> 0
B19: DSU Pune - STC | C19: MahaSTRIDE/10 | D19: 46218 | E19: 46082 | F19: 2649194 | G19: Committee Approved 05.08.2026 | I19: =F19 -> 2649194 | J19: =F19-H19-I19 -> 0 | M19: =H19 -> 0
B20: DSU Pune - STC | C20: MahaSTRIDE/12 | D20: 46218 | E20: 46113 | F20: 2812500 | G20: Committee Approved 05.08.2026 | I20: =F20 -> 2812500 | J20: =F20-H20-I20 -> 0 | M20: =H20 -> 0
B21: DSU Pune - STC | C21: MahaSTRIDE/13 | D21: 46253 | E21: 46143 | F21: 2741492 | G21: Received Tax invoice 19.08.2026 | I21: =F21 -> 2741492 | J21: =F21-H21-I21 -> 0 | M21: =H21 -> 0
B22: DSU Pune - STC | C22: MahaSTRIDE/14 | D22: 46253 | E22: 25% of Jun 25 | F22: 2741495 | G22: Received Proforma invoice 19.08.2026 | I22: =F22 -> 2741495 | J22: =F22-H22-I22 -> 0 | M22: =H22 -> 0
A23: 4 | B23: DSU CSN- Choice | C23: CCS/25-26/02-75 | D23: 16/02/2026 | E23: 46023 | F23: 5734901 | G23: Issued | H23: 5734901 | J23: =F23-H23-I23 -> 0 | K23: 13.07.2026 | L23: The MPR with attendance has not been attached. | O23: =H23 -> 5734901
B24: DSU CSN- Choice | C24: CCS/25-26/03-84 | D24: 16/03/2026 | E24: 46054 | F24: 4700625 | G24: Issued | H24: 4700625 | J24: =F24-H24-I24 -> 0 | K24: 13.07.2026 | O24: =H24 -> 4700625
B25: DSU CSN- Choice | C25: CCS/25-26/04-47 | D25: 23/04/2026 | E25: 46082 | F25: 3537097 | G25: submited 15.07.2026 objection | I25: =F25 -> 3537097 | J25: =F25-H25-I25 -> 0 | O25: =H25 -> 0
B26: DSU CSN- Choice | C26: CCS/26-27/06-107 | D26: 26.06.2026 | E26: 5% Mob Private Cap | F26: 5280000 | G26: Received 10.08.2026 25.08 | I26: =F26 -> 5280000 | J26: =F26-H26-I26 -> 0 | M26: =F26 -> 5280000
B27: DSU CSN- Choice | C27: CCS/26-27/06-108 | D27: 26.06.2026 | E27: 4% Submit AAP to DSP | F27: 4224000 | G27: Received 10.08.2026 25.08 | I27: =F27 -> 4224000 | J27: =F27-H27-I27 -> 0 | M27: =F27 -> 4224000
B28: DSU CSN- Choice | C28: CCS/26-27/06-110 | D28: 26.06.2026 | E28: 4% Progress Intervation | F28: 4224000 | G28: Received 10.08.2026 25.08 | I28: =F28 -> 4224000 | J28: =F28-H28-I28 -> 0 | M28: =F28 -> 4224000
B29: DSU CSN- Choice | C29: CCS/26-27/06-109 | D29: 26.06.2026 | E29: 2% Progress Intervation | F29: 2112001 | G29: Received 10.08.2026 25.08 | I29: =F29 -> 2112001 | J29: =F29-H29-I29 -> 0 | M29: =F29 -> 2112001
A30: 5 | B30: DSU Amra Linpico | C30: 40/2025-26 | D30: 18-03-2026 | E30: 46023 | F30: 1405176 | G30: Issued | H30: 1405176 | J30: =F30-H30-I30 -> 0 | K30: 21.07.2026 | L30: Substitution of the staff has been approved by IBRD/World Bank, and the contract amendment is in process. | O30: =H30 -> 1405176
B31: DSU Amra Linpico | C31: 42/2025-26 | D31: 27-03-2026 | E31: 46054 | F31: 1602686 | G31: Issued | H31: 1602686 | J31: =F31-H31-I31 -> 0 | K31: 21.07.2027 | O31: =H31 -> 1602686
B32: DSU Amra Linpico | C32: 42/2025-26 | D32: 27-03-2026 | E32: 46082 | F32: 1552946 | G32: Committee aproved 08.07.2026 | I32: =F32 -> 1552946 | J32: =F32-H32-I32 -> 0 | M32: =F32 -> 1552946
B33: DSU Amra Linpico | C33: 42/2025-26 | D33: 27-03-2026 | E33: 46113 | F33: 1625749 | G33: Committee aproved 08.07.2026 | I33: =F33 -> 1625749 | J33: =F33-H33-I33 -> 0 | M33: =F33 -> 1625749
B34: DSU Amra Linpico | C34: 14/2026-27 | D34: 46259 | E34: 46143 | F34: 2350861 | G34: Received Tax invoice 25.08.2026 | I34: =F34 -> 2350861 | J34: =F34-H34-I34 -> 0 | M34: =F34 -> 2350861
B35: DSU Amra Linpico | C35: 15/2026-27 | D35: 46259 | E35: 46174 | F35: 2583790 | G35: Received Tax invoice 25.08.2026 | I35: =F35 -> 2583790 | J35: =F35-H35-I35 -> 0 | M35: =F35 -> 2583790
B36: DSU Amra Linpico | C36: 13/2026-27 | D36: 46259 | E36: Due clearence of approved CVs Jul 25 -Apr 26 | F36: 4774938 | G36: Received Tax invoice 25.08.2026 | I36: =F36 -> 4774938 | J36: =F36-H36-I36 -> 0 | M36: =F36 -> 4774938
A37: 6 | B37: DSU Nagpur- E & Y | C37: IN91HR6L029540 | E37: 45839 | F37: 840952.71 | G37: Issued | H37: 840952.71 | J37: =F37-H37-I37 -> 0 | K37: 21.04.2026 | M37: =F37 -> 840952.71
B38: DSU Nagpur- E & Y | C38: IN91HR6L029397 | E38: 45870 | F38: 2215560.4 | G38: Issued | H38: 2215560.4 | J38: =F38-H38-I38 -> 0 | K38: 21.04.2026 | M38: =F38 -> 2215560.4
B39: DSU Nagpur- E & Y | C39: IN91HR6L029396 | E39: Sept.25 | F39: 4084337 | G39: Issued | H39: 4084337 | J39: =F39-H39-I39 -> 0 | K39: 21.04.2026 | M39: =F39 -> 4084337
B40: DSU Nagpur- E & Y | C40: IN91HR6L030924 | E40: Oct.2025 | F40: 5703517 | G40: Issued | H40: 5703517 | J40: =F40-H40-I40 -> 0 | K40: 21.04.2026 | M40: =F40 -> 5703517
...

Sheet BILL MEET 
A1: Submission of Bills for Approval in Meeting 04.09.2026 – MahaSTRIDE Operation
A2: Sr.No. | B2: Particulars | C2: Invoice No. | D2: Invoice Date | E2: Billing Month | F2: Bills amount Rs | G2: Received Date/ Status of Bill | H2: Remarks | I2: Aproved Bills-for-- Treasury | J2: Order Date | K2: Remarks, if any
A3: 1 | B3: DSU Nashik - KPMG | C3: KASP-HR/A100536 | D3: 30/07/2026 | E3: 46143 | F3: 5175888 | G3: Received Tax invoice 18.08.2026 | H3: Verification in process | K3: Substitution of the staff has been approved by IBRD/World Bank, and the contract amendment is in process. | L3: =#REF!-I3 -> #REF!
C4: KASP-HR/A100566 | D4: 30/07/2026 | E4: 46174 | F4: 5087025 | G4: Received Tax invoice 18.08.2026 | H4: Verification in process
C5: KASP-HR/A100611 | D5: 46247 | E5: Incecption Report | F5: 3431999 | G5: Received Tax invoice 18.08.2026 | H5: 4% of total yearly contract value for milestone base.
C6: KASP-HR/A100616 | D6: 46248 | E6: Private Capital Mobi | F6: 4290000 | G6: Received Tax invoice 18.08.2026 | H6: 5% of total yearly contract value for milestone base.
C7: KASP-HR/A100627 | D7: 46252 | E7: Public Disclosure | F7: 10296000 | G7: Received Tax invoice 18.08.2026 | H7: 12% of total yearly contract value for milestone base.
A8: 2 | B8: DSU Pune - STC | C8: MahaSTRIDE/13 | D8: 46253 | E8: 46143 | F8: 2741492 | G8: Received Tax invoice 20.08.2026 | H8: Verification in process | L8: =F8-I8 -> 2741492
A9: 3 | B9: DSU CSN- Choice | C9: CCS/25-26/04-47 | D9: 23/04/2026 | E9: 46082 | F9: 3537097 | G9: Objected on file- IVA report and deploy Man power
C10: CCS/26-27/06-107 | D10: 26.06.2026 | E10: 5% Mob Private Cap | F10: 5280000 | G10: Received Tax invoice 25.08.2026 | H10: Verification in process
C11: CCS/26-27/06-108 | D11: 26.06.2026 | E11: 4% out of 12 % timely preperation of AAP of DSP, submission to the State planning department of AAP of DSP. | F11: 4224000 | G11: Received Tax invoice 25.08.2026 | H11: Verification in process
C12: CCS/26-27/06-110 | D12: 26.06.2026 | E12: 4% out of 8 % for Tracking and Reporting of progress achievement of each intervention of AAP of DSP of all 8 Dist | F12: 4224000 | G12: Received Tax invoice 25.08.2026 | H12: Verification in process
C13: CCS/26-27/06-109 | D13: 26.06.2026 | E13: 2% out of 8 % for Tracking and Reporting of progress achievement of each intervention of AAP of DSP of all 8 Dist | F13: 2112001 | G13: Received Tax invoice 25.08.2026 | H13: Verification in process
A14: 4 | B14: DSU Amravati Linpico | C14: 14/2026-27 | D14: 46259 | E14: 46143 | F14: 2350861 | G14: Received Tax invoice 25.08.2026 | H14: Verification in process
C15: 15/2026-27 | D15: 46259 | E15: 46174 | F15: 2583790 | G15: Received Tax invoice 25.08.2026 | H15: Verification in process
C16: 13/2026-27 | D16: 46259 | E16: Due clearence of approved CVs Jul 2025 -Apr 2026 | F16: 4774938 | G16: Received Tax invoice 25.08.2026 | H16: Verification in process
A17: 5 | B17: DSU Nagpur - E & Y LLP | C17: IN91HR7L004148 | D17: 19.05.2026 | E17: 5%Deliverable Based | F17: 4595062 | G17: IVA report is still not received | H17: World Bank approval for the IVA report is awaited
C18: IN91HR7L005348 | D18: 03.06.2026 | E18: 4%Deliverable Based | F18: 3676049 | G18: Div Comm acceptance confirmation received 21.07.2026 31.08.2026 | H18: As per last MoM, Required redrafted report from 30.06.2025 to 30.09.2025 and 01.10.2025 to 31.03.2026 is still awaited | L18: =F17-I18 -> 4595062
C19: IN91HR7L011745 | D19: 12.08.2026 | E19: 46174 | F19: 5743827 | G19: Received Tax invoice 31.08.2026 | H19: Verification in process
C20: IN91HR7L011976 | D20: 14.08.2026 | E20: 46204 | F20: 5743827 | G20: Received Tax invoice 31.08.2026 | H20: Verification in process | L20: =F18-I20 -> 3676049
A21: 6 | B21: ICARE | C21: ICARE/M/2627/004 | D21: 01.08.2026 | E21: 46204 | F21: 1307888 | G21: Received 13.08.2026 | L21: =F21-I21 -> 1307888
A22: 7 | B22: IIM Ahmadabad IDDP | C22: 2681000049 | D22: 31.08.2026 | E22: 46235 | F22: 2000000 | G22: Received 03.09.2026
A23: 8 | B23: E & Y LLP Agriculture In MITRA | C23: IN91WB71000949 | D23: 23.06.2026 | E23: 16 th May to 15th June 2026 | F23: 1244900 | G23: Received 23.06.2026 | H23: Bill For Project Based Initiative for Agriculture and allied sector
A24: 6 | B24: AI Training Karjat | C24: 09/2026-27 | D24: 29.07.2026 | E24: 13-14 July | F24: 624810 | G24: Bill received on 29.07.2026 | H24: Approved in Meeting 05.08.2026
C25: 10/2026-27 | D25: 29.07.2026 | E25: 27-28 July | F25: 631300 | G25: Bill received on 29.07.2026 | H25: Approved in Meeting 05.08.2026 | L25: =F25-I25 -> 631300
A26: 7 | B26: IVA -Lochan & Co. | E26: Last Balance IR 75% 50% | L26: =F26-I26 -> 0
C27: LC/EInv/25Jul16 | D27: 45937 | E27: =F27-I27 -> 962891.6 | F27: 1925783.6 | I27: 962892 | J27: 11.03.2026 | K27: Pending | L27: =F27-I27 -> 962891.6
C28: LC/EInv/25Jul17 | D28: 45937 | E28: =F28-I28 -> 268714.36 | F28: 358285.36 | I28: 89571 | J28: 11.03.2026 | L28: =F28-I28 -> 268714.36
C29: LC/EInv/25Jul18 | D29: 45937 | E29: =F29-I29 -> 268713.36 | F29: 358285.36 | I29: 89572 | J29: 11.03.2026 | L29: =F29-I29 -> 268713.36
C30: LC/EInv/25Jul19 | D30: 45937 | E30: =F30-I30 -> 268713.36 | F30: 358285.36 | I30: 89572 | J30: 11.03.2026 | L30: =F30-I30 -> 268713.36
E31: =SUM(E27:E30) -> 1769032.7 | F31: =SUM(F27:F30) -> 3000639.7 | L31: =F31-I31 -> 3000639.7
L32: =F32-I32 -> 0
L33: =F33-I33 -> 0
L34: =F34-I34 -> 0
L35: =F35-I35 -> 0
L36: =F36-I36 -> 0
L37: =F37-I37 -> 0
L38: =F38-I38 -> 0
L39: =F39-I39 -> 0
L40: =F40-I40 -> 0
...

Sheet STATUS
A1: Bills Status as on 31/08/2026 – MahaSTRIDE Operation BILLS To Be Submitted on file for release Bill amount
A2: Sr.No. | B2: Particulars | C2: Invoice No. | D2: Date | E2: Billing Month | F2: Received Bills amount Rs | G2: Status | H2: Aproved Bills-for-- Treasury | I2: Order Date | J2: Remarks, if any
A3: 1 | B3: PMC - KPMG 3062986 part | C3: KASP-MH/100069 | D3: 25/05/2026 | E3: 10% Deliverable | F3: 3657952 | G3: Approved by committee 05.08.2026 File for submission email received | K3: =F3-H3 -> 3657952
B4: PMC - KPMG 3062986 Part | C4: KASP-MH/A100127 | D4: 46184 | E4: NOV. 2025 | F4: 1024240 | G4: Bill PASSED on 04.08.2026 | H4: 970255 | I4: 15.07.2026 | K4: =F4-H4 -> 53985
E5: TOTAL-A | F5: =SUM(F3:F4) -> 4682192 | K5: =F5-H5 -> 4682192
A6: 2 | B6: DSU Nashik-KPMG 3076998 | C6: KASP-HR/900709 | D6: 46171 | E6: 46023 | F6: 4633825 | G6: Bill PASSED on 04.08.2026 | H6: 4633825 | I6: 22.07.2026 | J6: Substitution of the staff has been approved by IBRD/World Bank, and the contract amendment is in process. | K6: =F6-H6 -> 0
B7: DSU Nashik-KPMG 3076998 | C7: KASP-HR/A100228 | D7: 31/05/2026 | E7: 46054 | F7: 5067348 | G7: Bill PASSED on 04.08.2026 | H7: 5067348 | I7: 22.07.2026 | K7: =F7-H7 -> 0
B8: DSU Nashik-KPMG 3076998 | C8: KASP-HR/A100218 | D8: 31/05/2026 | E8: 46082 | F8: 5158115 | G8: Bill PASSED on 04.08.2026 | H8: 5158115 | I8: 22.07.2026 | K8: =F8-H8 -> 0
B9: DSU Nashik-KPMG 3076998 | C9: KASP-HR/A100345 | D9: 29/06/2026 | E9: 46113 | F9: 5334952 | G9: Approved by committee 05.08.2026 File for submission | K9: =F9-H9 -> 5334952
B10: DSU Nashik-KPMG 3076998 | C10: KASP-HR/A100536 | D10: 30/07/2026 | E10: 46143 | F10: 5175888 | G10: Received Tax invoice 10.08.2026
B11: DSU Nashik-KPMG 3076998 | C11: KASP-HR/A100566 | D11: 30/07/2026 | E11: 46174 | F11: 5087025 | G11: Received Tax invoice 18.08.2026
B12: DSU Nashik-KPMG 3076998 | C12: KASP-HR/A100611 | D12: 46247 | E12: Incecption Report | F12: 3431999 | G12: Received Tax invoice 18.08.2026
B13: DSU Nashik-KPMG 3076998 | C13: KASP-HR/A100616 | D13: 46248 | E13: Private Capital Mobi | F13: 4290000 | G13: Received Tax invoice 18.08.2026
B14: DSU Nashik-KPMG 3076998 | C14: KASP-HR/A100627 | D14: 46252 | E14: Public Disclosure | F14: 10296000 | G14: Received Tax invoice 18.08.2026
B15: DSU Nashik-KPMG 3076998 | C15: KASP-HR/A100702 | D15: 3108/2026 | E15: 46204 | F15: 5087025 | G15: Received Tax invoice 02.09.2026
E16: TOTAL-B | F16: =SUM(F6:F9) -> 20194240 | K16: =F16-H16 -> 20194240
A17: 3 | B17: DSU Pune - STC 3076970 | C17: MahaSTRIDE/DSU/Pune/005 | D17: 46099 | E17: Oct.2025 | F17: 2512984 | G17: Bill PASSED on 04.08.2026 | H17: 2512984 | I17: 22.07.2026 | J17: Substitution of the staff has been approved by IBRD/World Bank, and the contract amendment is in process. | K17: =F17-H17 -> 0
B18: DSU Pune - STC 3076970 | C18: MahaSTRIDE/DSU/Pune/006 | D18: 46099 | E18: Nov.2025 | F18: 2760750 | G18: Bill PASSED on 04.08.2026 | H18: 2760750 | I18: 22.07.2026 | K18: =F18-H18 -> 0
B19: DSU Pune - STC 3076970 | C19: MahaSTRIDE/DSU/Pune/007 | D19: 46099 | E19: Dec.2025 | F19: 2681371 | G19: Bill PASSED on 04.08.2026 | H19: 2681371 | I19: 22.07.2026 | K19: =F19-H19 -> 0
B20: DSU Pune - STC 3076970 | C20: MahaSTRIDE/8 | D20: 46150 | E20: 46023 | F20: 2610484 | G20: File Submitted 31.07.2026 Objected | K20: =F20-H20 -> 2610484
B21: DSU Pune - STC 3076970 | C21: MahaSTRIDE/9 | D21: 46150 | E21: 46054 | F21: 2475000 | G21: File Submitted 31.07.2026 Kolhapur Obj Konale | K21: =F21-H21 -> 2475000
B22: DSU Pune - STC 3076970 | C22: MahaSTRIDE/10 | D22: 46218 | E22: 46082 | F22: 2649194 | G22: Approved by committee 05.08.2026 File submitted | K22: =F22-H22 -> 2649194
B23: DSU Pune - STC 3076970 | C23: MahaSTRIDE/11 | D23: 46218 | E23: Jun 25 to Mar 26 25% | F23: 7307019 | G23: Report awaited | K23: =F23-H23 -> 7307019
B24: DSU Pune - STC 3076970 | C24: MahaSTRIDE/12 | D24: 46218 | E24: 46113 | F24: 2812500 | G24: Approved by committee 05.08.2026 File submitted | K24: =F24-H24 -> 2812500
B25: DSU Pune - STC 3076970 | C25: MahaSTRIDE/13 | D25: 46253 | E25: 46143 | F25: 2741492 | G25: Received Tax invoice 20.08.2026
B26: DSU Pune - STC 3076970 | C26: MahaSTRIDE/14 | D26: 46254 | E26: Jun 25 to Mar 26 25% Remun | F26: 5553334 | G26: Received Proforma invoice 20.08.2026
E27: TOTAL-C | F27: =SUM(F17:F24) -> 25809302 | K27: =F27-H27 -> 25809302
A28: 4 | B28: DSU CSN- Choice 3081210 | C28: CCS/25-26/02-75 | D28: 16/02/2026 | E28: 46023 | F28: 5782137 | G28: Bill PASSED on 10.08.2026 | H28: 5760363 | I28: 13.07.2026 | J28: The MPR with attendance has not been attached. | K28: =F28-H28 -> 21774
B29: DSU CSN- Choice 3081210 | C29: CCS/25-26/03-84 | D29: 16/03/2026 | E29: 46054 | F29: 4757544 | G29: Bill PASSED on 10.08.2026 | H29: 4700625 | I29: 13.07.2026 | K29: =F29-H29 -> 56919
B30: DSU CSN- Choice 3081210 | C30: CCS/25-26/04-47 | D30: 23/04/2026 | E30: 46082 | F30: 3537097 | G30: Bill file submited 15.07.2026 Objection achievement | H30: =3495968 -> 3495968 | K30: =F30-H30 -> 41129
B31: DSU CSN- Choice 3081210 | C31: CCS/26-27/06-107 | D31: 26.06.2026 | E31: 5% Mob Private Cap | F31: 5280000 | G31: Received Tax invoice 10.08.2026 | K31: =F31-H31 -> 5280000
B32: DSU CSN- Choice 3081210 | C32: CCS/26-27/06-108 | D32: 26.06.2026 | E32: 4% Submit AAP to DSP | F32: 4224000 | G32: Received Tax invoice 10.08.2026 | K32: =F32-H32 -> 4224000
B33: DSU CSN- Choice 3081210 | C33: CCS/26-27/06-110 | D33: 26.06.2026 | E33: 4% Progress Intervation | F33: 4224000 | G33: Received Tax invoice 10.08.2026
B34: DSU CSN- Choice 3081210 | C34: CCS/26-27/06-109 | D34: 26.06.2026 | E34: 2% Progress Intervation | F34: 2112001 | G34: Received Tax invoice 10.08.2026 | K34: =F34-H34 -> 2112001
E35: TOTAL-D | F35: =SUM(F28:F34) -> 29916779 | K35: =F35-H35 -> 29916779
A36: 5 | B36: DSU Amra Linpico 3077322 | C36: 40/2025-26 | D36: 18-03-2026 | E36: 46023 | F36: 1405176 | G36: Bill PASSED on 04.08.2026 | H36: 1405176 | I36: 21.07.2026 | J36: Substitution of the staff has been approved by IBRD/World Bank, and the contract amendment is in process. | K36: =F36-H36 -> 0
B37: DSU Amra Linpico 3077322 | C37: 42/2025-26 | D37: 27-03-2026 | E37: 46054 | F37: 1602686 | G37: Bill PASSED on 04.08.2026 | H37: 1602686 | I37: 21.07.2027 | K37: =F37-H37 -> 0
B38: DSU Amra Linpico 3077322 | C38: 03/2026-27 | D38: 46184 | E38: 46082 | F38: 1552946 | G38: Approved by committee File for submitted | K38: =F38-H38 -> 1552946
B39: DSU Amra Linpico 3077322 | C39: 04/2026-27 | D39: 46214 | E39: 46113 | F39: 1625749 | G39: Approved by committee File for submitted | K39: =F39-H39 -> 1625749
B40: DSU Amra Linpico 3077322 | C40: 14/2026-27 | D40: 46259 | E40: 46143 | F40: 2350861 | G40: Received Tax invoice 25.08.2026
...

Sheet BILLS 27 For Pay
A1: Bills as on 17/06/2026 – MahaSTRIDE Operation | K1: 3451A215 | M1: 3451A224 | O1: 3451A233
A2: Sr.No. | B2: Particulars | C2: Invoice No. | D2: Date | E2: Billing Month | F2: Received Bills amount Rs | G2: Status | H2: Aproved Bills-for-- Treasury | I2: Order Date | J2: Remarks, if any | K2: 10 Cont Services | L2: 26 Advertise | M2: 10 Cont Services | N2: 26 Advertise | O2: 06 Telephone | P2: 10 Cont Services | Q2: 13 Office Exp | R2: 14 Rent | S2: 17 Computer | T2: 26 Advertise | U2: 27 Minor Works | V2: 28 Prof Services | W2: 31 Graint in Aid
A3: 1 | B3: PMC - KPMG Advisory Services Pvt. Ltd. Part 1-3062986 | C3: KASP-MH/100069 | D3: 25/05/2026 | E3: 10% Deliverable | F3: 3657952 | G3: Committee Approved 05.08.2026 | H3: 3657952 | M3: =H3 -> 3657952
C4: KASP-MH/A100127 | D4: 46184 | E4: NOV. 2025 | F4: 1024240 | G4: Issued | H4: 970255 | I4: 15.07.2026 | K4: =H4 -> 970255
E5: TOTAL-A | F5: =SUM(F3:F4) -> 4682192
A6: 2 | B6: DSU Nashik KPMG 3076998 | C6: KASP-HR/A100169 | D6: 46160 | E6: 46023 | F6: 4633825 | G6: Issued | H6: 4633825 | I6: 22.07.2026 | J6: Substitution of the staff has been approved by IBRD/World Bank, and the contract amendment is in process. | M6: =H6 -> 4633825
B7: DSU Nashik KPMG 3076998 | C7: KASP-HR/A100228 | D7: 31/05/2026 | E7: 46054 | F7: 5067348 | G7: Issued | H7: 5067348 | I7: 22.07.2026 | M7: =H7 -> 5067348
B8: DSU Nashik KPMG 3076998 | C8: KASP-HR/A100218 | D8: 31/05/2026 | E8: 46082 | F8: 5158115 | G8: Issued | H8: 5158115 | I8: 22.07.2026 | M8: =H8 -> 5158115
B9: DSU Nashik KPMG 3076998 | C9: KASP-HR/A100345 | D9: 29/06/2026 | E9: 46113 | F9: 5334952 | G9: Committee Approved 05.08.2026 | H9: 5334952 | M9: {=H9:K9} -> 5334952 | N9: 0 | O9: 0 | P9: 0
B10: DSU Nashik KPMG 3076998 | C10: KASP-HR/A100536 | D10: 30/07/2026 | E10: 46143 | F10: 5175888 | G10: Received 10.08.2026 | M10: =F10 -> 5175888
B11: DSU Nashik KPMG 3076998 | C11: KASP-HR/A100566 | D11: 30/07/2026 | E11: 46174 | F11: 5087025 | G11: Received 10.08.2026 | M11: =F11 -> 5087025
B12: DSU Nashik KPMG 3076998 | C12: KASP-HR/A100611 | D12: 46247 | E12: Incecption Report | F12: 3431999 | G12: Received Tax invoice 18.08.2026 | K12: =F12 -> 3431999
B13: DSU Nashik KPMG 3076998 | C13: KASP-HR/A100616 | D13: 46248 | E13: Private Capital Mobi | F13: 4290000 | G13: Received Tax invoice 18.08.2026 | K13: =F13 -> 4290000
B14: DSU Nashik KPMG 3076998 | C14: KASP-HR/A100627 | D14: 46252 | E14: Public Disclosure | F14: 10296000 | G14: Received Tax invoice 18.08.2026 | K14: =F14 -> 10296000
E15: TOTAL-B | F15: =SUM(F6:F14) -> 48475152
A16: 3 | B16: DSU Pune - STC 3076970 | C16: MahaSTRIDE/DSU/Pune/005 | D16: 46099 | E16: Oct.2025 | F16: 2512984 | G16: Issued | H16: 2512984 | I16: 21.07.2026 | J16: Substitution of the staff has been approved by IBRD/World Bank, and the contract amendment is in process. | K16: =F16 -> 2512984
B17: DSU Pune - STC 3076970 | C17: MahaSTRIDE/DSU/Pune/006 | D17: 46099 | E17: Nov.2025 | F17: 2760750 | G17: Issued | H17: 2760750 | I17: 21.07.2026 | K17: =F17 -> 2760750
B18: DSU Pune - STC 3076970 | C18: MahaSTRIDE/DSU/Pune/007 | D18: 46099 | E18: Dec.2025 | F18: 2681371 | G18: Issued | H18: 2681371 | I18: 21.07.2026 | K18: =F18 -> 2681371
B19: DSU Pune - STC 3076970 | C19: MahaSTRIDE/8 | D19: 46150 | E19: 46023 | F19: 2610484 | G19: aproved 08.07.2026 File Submited | H19: 2610484 | K19: =H19 -> 2610484
B20: DSU Pune - STC 3076970 | C20: MahaSTRIDE/9 | D20: 46150 | E20: 46054 | F20: 2475000 | G20: aproved 08.07.2026 File Submited | H20: 2475000 | K20: =H20 -> 2475000
B21: DSU Pune - STC 3076970 | C21: MahaSTRIDE/10 | D21: 46218 | E21: 46082 | F21: 2649194 | G21: Committee Approved 05.08.2026 | H21: 2649194 | K21: =H21 -> 2649194
B22: DSU Pune - STC 3076970 | C22: MahaSTRIDE/11 | D22: 46218 | E22: Jun 25 to Mar 26 25% | F22: 7307019 | G22: Received on 15.07.2026
B23: DSU Pune - STC 3076970 | C23: MahaSTRIDE/12 | D23: 46218 | E23: 46113 | F23: 2812500 | G23: Committee Approved 05.08.2026 | H23: 2812500 | K23: =H23 -> 2812500
B24: DSU Pune - STC 3076970 | C24: MahaSTRIDE/13 | D24: 46253 | E24: 46143 | F24: 2741492 | G24: Received Tax invoice 19.08.2026 | H24: 2741492 | K24: =H24 -> 2741492
B25: DSU Pune - STC 3076970 | C25: MahaSTRIDE/14 | D25: 46253 | E25: 25% of Jun 25 | F25: 2741495 | G25: Received Proforma invoice 19.08.2026 | H25: 5553334 | K25: =H25 -> 5553334
E26: TOTAL-C | F26: =SUM(F16:F24) -> 28550794
A27: 4 | B27: DSU CSN- Choice 3081210 | C27: CCS/25-26/02-75 | D27: 16/02/2026 | E27: 46023 | F27: 5782137 | G27: Issued | H27: 5734901 | I27: 13.07.2026 | J27: The MPR with attendance has not been attached. | M27: =H27 -> 5734901
B28: DSU CSN- Choice 3081210 | C28: CCS/25-26/03-84 | D28: 16/03/2026 | E28: 46054 | F28: 4757544 | G28: Issued | H28: 4700625 | I28: 13.07.2026 | M28: =H28 -> 4700625
B29: DSU CSN- Choice 3081210 | C29: CCS/25-26/04-47 | D29: 23/04/2026 | E29: 46082 | F29: 3537097 | G29: submited 15.07.2026 objection | H29: =3495968 -> 3495968 | M29: =H29 -> 3495968
B30: DSU CSN- Choice 3081210 | C30: CCS/26-27/06-107 | D30: 26.06.2026 | E30: 5% Mob Private Cap | F30: 5280000 | G30: Received 10.08.2026 25.08 | K30: =F30 -> 5280000
B31: DSU CSN- Choice 3081210 | C31: CCS/26-27/06-108 | D31: 26.06.2026 | E31: 4% Submit AAP to DSP | F31: 4224000 | G31: Received 10.08.2026 25.08 | K31: =F31 -> 4224000
B32: DSU CSN- Choice 3081210 | C32: CCS/26-27/06-110 | D32: 26.06.2026 | E32: 4% Progress Intervation | F32: 4224000 | G32: Received 10.08.2026 25.08 | K32: =F32 -> 4224000
B33: DSU CSN- Choice 3081210 | C33: CCS/26-27/06-109 | D33: 26.06.2026 | E33: 2% Progress Intervation | F33: 2112001 | G33: Received 10.08.2026 25.08 | K33: =F33 -> 2112001
E34: TOTAL-D | F34: =SUM(F27:F33) -> 29916779
A35: 5 | B35: DSU Amra Linpico 3077322 | C35: 40/2025-26 | D35: 18-03-2026 | E35: 46023 | F35: 1405176 | G35: Issued | H35: 1405176 | I35: 21.07.2026 | J35: Substitution of the staff has been approved by IBRD/World Bank, and the contract amendment is in process. | M35: =H35 -> 1405176
B36: DSU Amra Linpico 3077322 | C36: 42/2025-26 | D36: 27-03-2026 | E36: 46054 | F36: 1602686 | G36: Issued | H36: 1602686 | I36: 21.07.2027 | M36: =H36 -> 1602686
B37: DSU Amra Linpico 3077322 | C37: 42/2025-26 | D37: 27-03-2026 | E37: 46082 | F37: 1552946 | G37: Committee aproved 08.07.2026 | H37: 1552946 | K37: =F37 -> 1552946
B38: DSU Amra Linpico 3077322 | C38: 42/2025-26 | D38: 27-03-2026 | E38: 46113 | F38: 1625749 | G38: Committee aproved 08.07.2026 | H38: 1625749 | K38: =F38 -> 1625749
B39: DSU Amra Linpico 3077322 | C39: 14/2026-27 | D39: 46259 | E39: 46143 | F39: 2350861 | G39: Received Tax invoice 25.08.2026 | K39: =F39 -> 2350861
B40: DSU Amra Linpico 3077322 | C40: 15/2026-27 | D40: 46259 | E40: 46174 | F40: 2583790 | G40: Received Tax invoice 25.08.2026 | K40: =F40 -> 2583790
...

Sheet MahaSTRIDE BILLS 26
A1: Status of Approved and pending bills as on 18/03/2026 – MahaSTRIDE Operation
A2: Sr.No. | B2: Particulars | C2: Invoice No. | D2: Date | E2: Billing Month | F2: Received 70/75% Bills amount Rs | G2: Status | H2: Aproved Bills-for-- Treasury | I2: Order Date | J2: Received 30/25% Bills amount Rs | K2: Bill Release Amount Rs
A3: 1 | B3: PMC - KPMG Advisory Services Pvt. Ltd. 3062986 | C3: KASP-MH/900033 | D3: 28/04/2025 | E3: 45717 | F3: 1877746 | G3: ISSUED | H3: =341386+1453760 -> 1795146 | I3: 23.02.2026 | J3: =(F3/7)*3 -> 804748.29 | K3: 0 | L3: =F3-H3 -> 82600 | N3: =F3/10000000 -> 0.1877746
C4: KASP-MH/900103 | D4: 45906 | E4: 45748 | F4: 1877746 | G4: ISSUED | H4: =341386+1510754 -> 1852140 | I4: 23.02.2026 | J4: =(F4/7)*3 -> 804748.29 | K4: 0 | L4: =F4-H4 -> 25606 | N4: =F4/10000000 -> 0.1877746
C5: KASP-MH/900132 | D5: 45778 | E5: 45778 | F5: 1621686 | G5: ISSUED | H5: =341386+1172920 -> 1514306 | I5: 23.02.2026 | J5: =(F5/7)*3 -> 695008.29 | K5: 0 | L5: =F5-H5 -> 107380 | N5: =F5/10000000 -> 0.1621686
C6: KASP-MH/900228 | D6: 45809 | E6: 45809 | F6: 2133806 | G6: ISSUED | H6: =307247+1715602 -> 2022849 | I6: 23.02.2026 | J6: =(F6/7)*3 -> 914488.29 | K6: 0 | L6: =F6-H6 -> 110957 | N6: =F6/10000000 -> 0.2133806
C7: KASP-MH/900309 | D7: 45839 | E7: 45839 | F7: 2084246 | G7: ISSUED | H7: =297336+1718080 -> 2015416 | I7: 23.02.2026 | J7: =(F7/7)*3 -> 893248.29 | K7: 0 | L7: =F7-H7 -> 68830 | N7: =F7/10000000 -> 0.2084246
C8: KASP-MH/900423 | D8: 30/09/2025 | E8: 45870 | F8: 2133806 | G8: ISSUED | H8: 2018166 | I8: 20.03.2026 | J8: =(F8/7)*3 -> 914488.29 | K8: 0 | L8: =F8-H8 -> 115640 | N8: 341386
C9: KASP-MH/900645 | D9: 26/12/2025 | E9: Sept.25 | F9: 2133806 | G9: ISSUED | H9: 2048453 | I9: 20.03.2026 | J9: =(F9/7)*3 -> 914488.29 | K9: 0 | L9: =F9-H9 -> 85353 | N9: 1676780 | O9: =N8+N9 -> 2018166
C10: KASP-MH/900468 | D10: 30/12/2025 | E10: Oct.25 | F10: 2133807 | G10: ISSUED | H10: 1996141 | I10: 20.03.2026 | J10: =(F10/7)*3 -> 914488.71 | K10: 0 | L10: =F10-H10 -> 137666 | N10: 341386
C11: KASP-MH/900741 | D11: 16.02.2026 | E11: Nov.2025 | F11: 1877746 | G11: ISSUED | H11: 1835069 | I11: 20.03.2026 | J11: =(F11/7)*3 -> 804748.29 | K11: 0 | L11: =F11-H11 -> 42677 | N11: 1707067 | O11: =N10+N11 -> 2048453
C12: KASP-MH/900745 | D12: 17.02.2026 | E12: Dec.2025 | F12: 1877746 | G12: ISSUED | H12: 1701534 | I12: 20.03.2026 | J12: =(F12/7)*3 -> 804748.29 | K12: 0 | L12: =F12-H12 -> 176212 | N12: 319361
C13: KASP-MH/900759 | D13: 20.02.2026 | E13: Jan.2026 | F13: 1877746 | G13: ISSUED | H13: 1770368 | I13: 20.03.2026 | J13: =(F13/7)*3 -> 804748.29 | K13: 0 | L13: =F13-H13 -> 107378 | N13: 1676780 | O13: =N12+N13 -> 1996141
C14: KASP-MH/900806 | D14: 28.02.2026 | E14: Feb.2026 | F14: 1877746 | G14: ISSUED | H14: 1777152 | I14: 20.03.2026 | J14: =(F14/7)*3 -> 804748.29 | K14: 0 | L14: =F14-H14 -> 100594 | O14: =SUM(O8:O13) -> 6062760
C15: KASP-MH/900265 | D15: 29/07/2025 | E15: Milestone Deliverable | F15: 3657952 | G15: ISSUED | H15: 3657952 | I15: 23.02.2026 | J15: =(F15/7)*3 -> 1567693.7 | K15: 0 | L15: =F15-H15 -> 0 | M15: =L15/10000000 -> 0 | N15: =#REF!/10000000 -> #REF!
E16: Total A | F16: =SUM(F3:F15) -> 27165585 | H16: =SUM(H3:H15) -> 26004692 | K16: =SUM(K3:K15) -> 0 | L16: =F16-H16 -> 1160893
A17: 2 | B17: District Strategic Unit (DSU) | C17: 3451A215 10-Cont Services
B18: Division : Nashik - KPMG Advisory 3076998 | C18: KASP-HR/900709 | D18: 30/09/2025 | E18: July & Aug.25 | F18: 3924291.8 | G18: ISSUED | H18: 3710823 | I18: 11.03.2026 | J18: =H18/3 -> 1236941 | K18: 0 | N18: =F18/10000000 -> 0.39242918
C19: KASP-HR/900762 | D19: 16/10/2025 | E19: Sept.25 | F19: 3823238 | G19: ISSUED | H19: 3823238 | I19: 11.03.2026 | J19: =H19/3 -> 1274412.7 | K19: 0 | L19: =SUM(F18:F19) -> 7747529.8 | M19: =L19/10000000 -> 0.77475298 | N19: =F19/10000000 -> 0.3823238
B20: 3451A224 | C20: KASP-HR/901275 | D20: 28.01.2026 | E20: Oct.2025 | F20: 4005406 | G20: ISSUED | H20: 4005406 | I20: 24.03.2026 | J20: =H20/3 -> 1335135.3 | K20: 0
B21: 3451A224 | C21: KASP-HR/901277 | D21: 28.01.2026 | E21: Nov.2025 | F21: 4246022 | G21: ISSUED | H21: 4246022 | I21: 24.03.2026 | J21: =H21/3 -> 1415340.7 | K21: 0
B22: 3451A224 | C22: KASP-HR/901289 | D22: 31.01.2026 | E22: Dec.2025 | F22: 4527189 | G22: ISSUED | H22: 4527189 | I22: 24.03.2026 | J22: =H22/3 -> 1509063 | K22: 0
E23: Sub-total B | F23: =SUM(F18:F22) -> 20526147 | H23: =SUM(H18:H22) -> 20312678 | K23: =SUM(K20:K22) -> 0 | L23: =F23-H23 -> 213468.78
A24: 3 | B24: Division : Pune - STC 3076970 | C24: MahaSTRIDE/DSU/Pune/001 | D24: 25/07/2025 | E24: 45833 | F24: 385250 | G24: ISSUED | H24: 385250 | I24: 24.03.2026 | J24: =H24/3 -> 128416.67 | N24: =F24/10000000 -> 0.038525 | P24: 358285
C25: MahaSTRIDE/DSU/Pune/002 | D25: 45877 | E25: 45863 | F25: 1382176 | G25: ISSUED | H25: 1382176 | I25: 24.03.2026 | J25: =H25/3 -> 460725.33 | N25: =F25/10000000 -> 0.1382176 | P25: =P24*0.25 -> 89571.25
C26: MahaSTRIDE/DSU/Pune/003 | D26: 45878 | E26: 45870 | F26: 2007096.8 | G26: ISSUED | H26: 2007096.8 | I26: 24.03.2026 | J26: =H26/3 -> 669032.26 | N26: =F26/10000000 -> 0.20070968 | P26: =P25*0.18 -> 16122.825
C27: MahaSTRIDE/DSU/Pune/004 | D27: 18/10/2025 | E27: Sept.25 | F27: 2456750 | G27: ISSUED | H27: 2456750 | I27: 24.03.2026 | J27: =H27/3 -> 818916.67 | L27: =SUM(F24:F27) -> 6231272.8 | M27: =L27/10000000 -> 0.62312728 | N27: =F27/10000000 -> 0.245675
E28: Sub-total C | F28: =SUM(F24:F27) -> 6231272.8 | H28: =SUM(H24:H27) -> 6231272.8 | K28: =SUM(K24:K27) -> 0
A29: 4 | B29: Division : CSN- Choice Consultancy | C29: CCSPT/25-26/07-01 | D29: 25/07/2025 | E29: 45833 | F29: 2795000 | G29: ISSUED | H29: 2787500 | I29: 24.03.2026 | J29: =H29/3 -> 929166.67 | N29: =#REF!/10000000 -> #REF!
C30: CCS/25-26/08-04 | D30: 45969 | E30: 45863 | F30: 5419597 | G30: ISSUED | H30: 5419597 | I30: 24.03.2026 | J30: =H30/3 -> 1806532.3
C31: CCS/25-26/09-25 | D31: 16/09/2025 | E31: 45870 | F31: 6104879 | G31: ISSUED | H31: 6104879 | I31: 24.03.2026 | J31: =H31/3 -> 2034959.7
C32: CCS/25-26/10-13 | D32: 13/10/2025 | E32: Sept.25 | F32: 6540000 | G32: ISSUED | H32: 6540000 | I32: 24.03.2026 | J32: =H32/3 -> 2180000
C33: CCS/25-26/11-43 | D33: 13/11/2025 | E33: Oct.2025 | F33: 6541331 | G33: ISSUED | H33: 6541331 | I33: 24.03.2026 | J33: =H33/3 -> 2180443.7
C34: CCS/25-26/01-39 | D34: 22/01/2026 | E34: Nov.2025 | F34: 5797501 | G34: ISSUED | H34: 5797501 | I34: 24.03.2026 | J34: =H34/3 -> 1932500.3
C35: CCS/25-26/01-40 | D35: 22/01/2026 | E35: Dec.2025 | F35: 5783952 | G35: ISSUED | H35: 5783952 | I35: 24.03.2026 | J35: =H35/3 -> 1927984 | L35: =SUM(F29:F35) -> 38982260 | M35: =L35/10000000 -> 3.898226
E36: Sub-total D | F36: =SUM(F29:F35) -> 38982260 | H36: =SUM(H29:H35) -> 38974760 | K36: =SUM(K29:K35) -> 0
A37: 5 | B37: Division : Amravati - Limpico & Co. 3451A224 | C37: 10-2025-26 | D37: 45901 | E37: 45809 | F37: 525724 | G37: ISSUED | H37: 482279 | I37: 23.03.2026 | N37: =F37/10000000 -> 0.0525724
C38: 11/2025-26 | D38: 45901 | E38: 45839 | F38: 1190856 | G38: ISSUED | H38: 1167424 | I38: 23.03.2026 | N38: =F38/10000000 -> 0.1190856
C39: 16/2025-26 | D39: 45922 | E39: 45870 | F39: 1350611 | G39: ISSUED | H39: 1350611 | I39: 23.03.2026 | N39: =F39/10000000 -> 0.1350611
C40: 21/2025-26 | D40: 45981 | E40: Sept-.2025 | F40: 1671415 | G40: ISSUED | H40: 1671415 | I40: 23.03.2026 | N40: =F40/10000000 -> 0.1671415
...

Sheet EXPEND
A1: आर्थिक वर्ष 2026-27, ओ-07, 3451, सचिवालयीन आर्थिक सेवा 00, 092, इतर कार्यालये (00), (00) (02/3/4) महाराष्ट्र जिल्हास्तरीय विकासास चालना देण्यासाठी संस्थात्मक क्षमता सक्षमीकरण प्रकल्प-MahaSTRIDE (बाहय हिस्सा 70% - जागतिक बँक/30 राज्य‍ हिस्सा/ P for R) (कार्यक्रम) (3451A215/A224/A233) 06 ऑगस्ट, 2026 अखेर खर्च
B2: (रु. हजारात)
A3: अ.क्र. | B3: उददीष्ट | C3: अर्थसंकल्पीय तरतूद (3451ए215) | D3: झालेला खर्च | E3: अर्थसंकल्पीय तरतूद (3451ए224) | F3: झालेला खर्च | G3: अर्थसंकल्पीय तरतूद (3451ए233) | H3: झालेला खर्च | I3: एकूण अर्थसंकल्पीय तरतूद | J3: एकूण झालेला खर्च
A4: 1 | B4: 4 | C4: 5 | D4: 6 | E4: 7 | F4: 8 | G4: 9 | H4: 10 | I4: 11 | J4: 12
A5: 1 | B5: 01, वेतन | C5: 10800 | D5: 0 | E5: 4620 | F5: 0 | G5: 50000 | H5: ='[1]FIELD DETAIL'!N39 -> 0 | I5: =C5+E5+G5 -> 65420 | J5: =D5+F5+H5 -> 0
A6: 2 | B6: 06, दुरध्वनी, वीज व पाणी शुल्क | C6: 3500 | D6: 0 | E6: 1500 | F6: 0 | G6: 20000 | H6: ='BILLS 27 For Pay'!G138 -> 0 | I6: =C6+E6+G6 -> 25000 | J6: =D6+F6+H6 -> 0
A7: 3 | B7: 10, कंत्राटी सेवा | C7: 495800 | D7: ='BILLS 27 For Pay'!E139/1000 -> 160192.28 | E7: 212500 | F7: ='BILLS 27 For Pay'!F139/1000 -> 51054.461 | G7: 200000 | H7: ='BILLS 27 For Pay'!G139/1000 -> 50543.968 | I7: =C7+E7+G7 -> 908300 | J7: =D7+F7+H7 -> 261790.71
A8: 4 | B8: 11, देशांतर्गत प्रवास खर्च | C8: 7000 | D8: 0 | E8: 3000 | F8: 0 | G8: 20000 | H8: 0 | I8: =C8+E8+G8 -> 30000 | J8: =D8+F8+H8 -> 0
A9: 5 | B9: 13, कार्यालयीन खर्च | C9: 14000 | D9: 0 | E9: 6000 | F9: 0 | G9: 300000 | H9: ='BILLS 27 For Pay'!G141/1000 -> 21486.155 | I9: =C9+E9+G9 -> 320000 | J9: =D9+F9+H9 -> 21486.155
A10: 6 | B10: 14, भाडेपट्टी व कर | C10: 14000 | D10: 0 | E10: 6000 | F10: 0 | G10: 50000 | H10: ='BILLS 27 For Pay'!G142/1000 -> 4779 | I10: =C10+E10+G10 -> 70000 | J10: =D10+F10+H10 -> 4779
A11: 7 | B11: 16, प्रकाशने | C11: 1 | D11: 0 | E11: 1 | F11: 0 | G11: 1 | H11: 0 | I11: =C11+E11+G11 -> 3 | J11: =D11+F11+H11 -> 0
A12: 8 | B12: 17, संगणक खर्च | C12: 35000 | D12: 0 | E12: 15000 | F12: 0 | G12: 600000 | H12: ='BILLS 27 For Pay'!H144/1000 -> 4701.346 | I12: =C12+E12+G12 -> 650000 | J12: =D12+F12+H12 -> 4701.346
A13: 9 | B13: 21, पुरवठा व सामुग्री | C13: 1 | D13: 0 | E13: 1 | F13: 0 | G13: 10000 | H13: 0 | I13: =C13+E13+G13 -> 10002 | J13: =D13+F13+H13 -> 0
A14: 10 | B14: 24, पेट्रोल, तेल व वंगण | C14: 1 | D14: 0 | E14: 1 | F14: 0 | G14: 5000 | H14: 0 | I14: =C14+E14+G14 -> 5002 | J14: =D14+F14+H14 -> 0
A15: 11 | B15: 26, जाहीरात व प्रसिध्दी | C15: 58800 | D15: 0 | E15: 25200 | F15: 0 | G15: 60000 | H15: ='BILLS 27 For Pay'!G147/1000 -> 500 | I15: =C15+E15+G15 -> 144000 | J15: =D15+F15+H15 -> 500
A16: 12 | B16: 27, लहान बांधकामे | C16: 1 | D16: 0 | E16: 1 | F16: 0 | G16: 244999 | H16: 0 | I16: =C16+E16+G16 -> 245001 | J16: =D16+F16+H16 -> 0
A17: 13 | B17: 28, व्यावसायिक सेवा | C17: 110800 | D17: 0 | E17: 47500 | F17: 0 | G17: 80000 | H17: 0 | I17: =C17+E17+G17 -> 238300 | J17: =D17+F17+H17 -> 0
A18: 14 | B18: 31, सहाय्यक अनुदान (वेतनेतर) | C18: 7000 | D18: 0 | E18: 3000 | F18: 0 | G18: 550000 | H18: ='BILLS 27 For Pay'!W132/1000 -> 349600 | I18: =C18+E18+G18 -> 560000 | J18: =D18+F18+H18 -> 349600
B19: एकूण | C19: =SUM(C5:C18) -> 756704 | D19: =SUM(D5:D18) -> 160192.28 | E19: =SUM(E5:E18) -> 324324 | F19: =SUM(F5:F18) -> 51054.461 | G19: =SUM(G5:G18) -> 2190000 | H19: =SUM(H5:H18) -> 431610.47 | I19: =C19+E19+G19 -> 3271028 | J19: =D19+F19+H19 -> 642857.21

Sheet  DEMAND
A1: ओ-07, 3451, सचिवालयीन आर्थिक सेवा 00, 092, इतर कार्यालये (00), (00) (02/3/4) महाराष्ट्र जिल्हास्तरीय विकासास चालना देण्यासाठी संस्थात्मक क्षमता सक्षमीकरण प्रकल्प-MahaSTRIDE (बाहय हिस्सा 70% - जागतिक बँक/30 राज्य‍ हिस्सा/ P for R) (कार्यक्रम) (3451A215/A224/A233)
B2: (रु. हजारात)
A3: अ.क्र. | B3: उददीष्ट | C3: अर्थसंकल्पीय तरतूद (3451ए215) | D3: चार महिण्यासाठी मागणी रक्कम | E3: अर्थसंकल्पीय तरतूद (3451ए224) | F3: चार महिण्यासाठी मागणी रक्कम | G3: अर्थसंकल्पीय तरतूद (3451ए233) | H3: चार महिण्यासाठी मागणी रक्कम | I3: एकूण तरतूद | J3: एकूण मागणी
A4: 1 | B4: 4 | C4: 5 | D4: 6 | E4: 7 | F4: 8 | G4: 9 | H4: 10 | I4: 11 | J4: 12
A5: 1 | B5: 01, वेतन | C5: 10800 | D5: 0 | E5: 4620 | F5: 0 | G5: 50000 | H5: ='[1]FIELD DETAIL'!N39 -> 0 | I5: =C5+E5+G5 -> 65420 | J5: =D5+F5+H5 -> 0
A6: 2 | B6: 06, दुरध्वनी, वीज व पाणी शुल्क | C6: 3500 | D6: 0 | E6: 1500 | F6: 0 | G6: 20000 | H6: =G6/4 -> 5000 | I6: =C6+E6+G6 -> 25000 | J6: =D6+F6+H6 -> 5000
A7: 3 | B7: 10, कंत्राटी सेवा | C7: 495800 | D7: 150000 | E7: 212500 | F7: 50000 | G7: 200000 | H7: =46000+4000 -> 50000 | I7: =C7+E7+G7 -> 908300 | J7: =D7+F7+H7 -> 250000
A8: 4 | B8: 11, देशांतर्गत प्रवास खर्च | C8: 7000 | D8: 0 | E8: 3000 | F8: 0 | G8: 20000 | H8: 0 | I8: =C8+E8+G8 -> 30000 | J8: =D8+F8+H8 -> 0
A9: 5 | B9: 13, कार्यालयीन खर्च | C9: 14000 | D9: 0 | E9: 6000 | F9: 0 | G9: 300000 | H9: =G9/4 -> 75000 | I9: =C9+E9+G9 -> 320000 | J9: =D9+F9+H9 -> 75000
A10: 6 | B10: 14, भाडेपट्टी व कर | C10: 14000 | D10: 0 | E10: 6000 | F10: 0 | G10: 50000 | H10: 5000 | I10: =C10+E10+G10 -> 70000 | J10: =D10+F10+H10 -> 5000
A11: 7 | B11: 16, प्रकाशने | C11: 1 | D11: 0 | E11: 1 | F11: 0 | G11: 1 | H11: 0 | I11: =C11+E11+G11 -> 3 | J11: =D11+F11+H11 -> 0
A12: 8 | B12: 17, संगणक खर्च | C12: 35000 | D12: 0 | E12: 15000 | F12: 0 | G12: 600000 | H12: =G12/4 -> 150000 | I12: =C12+E12+G12 -> 650000 | J12: =D12+F12+H12 -> 150000
A13: 9 | B13: 21, पुरवठा व सामुग्री | C13: 1 | D13: 0 | E13: 1 | F13: 0 | G13: 10000 | H13: 0 | I13: =C13+E13+G13 -> 10002 | J13: =D13+F13+H13 -> 0
A14: 10 | B14: 24, पेट्रोल, तेल व वंगण | C14: 1 | D14: 0 | E14: 1 | F14: 0 | G14: 5000 | H14: 0 | I14: =C14+E14+G14 -> 5002 | J14: =D14+F14+H14 -> 0
A15: 11 | B15: 26, जाहीरात व प्रसिध्दी | C15: 58800 | D15: 1000 | E15: 25200 | F15: 300 | G15: 60000 | H15: =G15/4 -> 15000 | I15: =C15+E15+G15 -> 144000 | J15: =D15+F15+H15 -> 16300
B16: 27, लहान बांधकामे | C16: 1 | D16: 0 | E16: 1 | F16: 0 | G16: 244999 | H16: 20000 | I16: =C16+E16+G16 -> 245001 | J16: =D16+F16+H16 -> 20000
A17: 12 | B17: 28, व्यावसायिक सेवा | C17: 110800 | D17: 0 | E17: 47500 | F17: 0 | G17: 80000 | H17: 0 | I17: =C17+E17+G17 -> 238300 | J17: =D17+F17+H17 -> 0
A18: 13 | B18: 31, सहाय्यक अनुदान (वेतनेतर) | C18: 7000 | D18: 0 | E18: 3000 | F18: 0 | G18: 550000 | H18: 350000 | I18: =C18+E18+G18 -> 560000 | J18: =D18+F18+H18 -> 350000
B19: एकूण | C19: =SUM(C5:C18) -> 756704 | D19: =SUM(D5:D18) -> 151000 | E19: =SUM(E5:E18) -> 324324 | F19: =SUM(F5:F18) -> 50300 | G19: =SUM(G5:G18) -> 2190000 | H19: =SUM(H5:H18) -> 670000 | I19: =C19+E19+G19 -> 3271028 | J19: =D19+F19+H19 -> 871300

Sheet DEMAND-2
A1: ओ-07, 3451, सचिवालयीन आर्थिक सेवा 00, 092, इतर कार्यालये (00), (00) (02/3/4) महाराष्ट्र जिल्हास्तरीय विकासास चालना देण्यासाठी संस्थात्मक क्षमता सक्षमीकरण प्रकल्प-MahaSTRIDE (बाहय हिस्सा 70% - जागतिक बँक/30 राज्य‍ हिस्सा/ P for R) (कार्यक्रम) (3451A215/A224/A233)
B2: (रु. हजारात)
A3: अ.क्र. | B3: उददीष्ट | C3: अर्थसंकल्पीय तरतूद (3451ए215) | D3: BEAMS वर प्राप्त रक्कम | E3: झालेला खर्च | F3: अर्थसंकल्पीय तरतूद (3451ए224) | G3: BEAMS वर प्राप्त रक्कम | H3: झालेला खर्च | I3: अर्थसंकल्पीय तरतूद (3451ए233) | J3: BEAMS वर प्राप्त रक्कम | K3: झालेला खर्च | L3: BEAMS वर शिल्लक रक्कम | M3: BEAMS वर शिल्लक रक्कम | N3: BEAMS वर शिल्लक रक्कम | O3: Reappro
A4: 1 | B4: 2 | C4: 3 | D4: 4 | E4: 5 | F4: 6 | G4: 7 | H4: 8 | I4: 9 | J4: 10 | K4: 11 | L4: 12 | M4: 13 | N4: 14 | O4: Withdrawa | P4: Balance
A5: 1 | B5: 01, वेतन | C5: 10800 | D5: 0 | E5: 0 | F5: 4620 | G5: 0 | H5: 0 | I5: 50000 | L5: =D5-E5 -> 0 | M5: =G5-H5 -> 0 | N5: =J5-K5 -> 0
A6: 2 | B6: 06, दुरध्वनी, वीज व पाणी शुल्क | C6: 3500 | D6: 0 | E6: 0 | F6: 1500 | G6: 0 | H6: 0 | I6: 20000 | J6: 5000 | L6: =D6-E6 -> 0 | M6: =G6-H6 -> 0 | N6: =J6-K6 -> 5000
A7: 3 | B7: 10, कंत्राटी सेवा | C7: 495800 | D7: =150000+39664 -> 189664 | E7: ='BILLS 27 For Pay'!E139/1000 -> 160192.28 | F7: =212500+17000 -> 229500 | G7: =50000+17000 -> 67000 | H7: ='BILLS 27 For Pay'!F139/1000 -> 51054.461 | I7: 200000 | J7: =46000+4000 -> 50000 | K7: ='BILLS 27 For Pay'!G139/1000 -> 50543.968 | L7: =D7-E7 -> 29471.723 | M7: =G7-H7 -> 15945.539 | N7: =J7-K7 -> -543.968
A8: 4 | B8: 11, देशांतर्गत प्रवास खर्च | C8: 7000 | D8: 0 | E8: 0 | F8: 3000 | G8: 0 | H8: 0 | I8: 20000 | L8: =D8-E8 -> 0 | M8: =G8-H8 -> 0 | N8: =J8-K8 -> 0
A9: 5 | B9: 13, कार्यालयीन खर्च | C9: 14000 | D9: 0 | E9: 0 | F9: 6000 | G9: 0 | H9: 0 | I9: 300000 | J9: 75000 | K9: ='BILLS 27 For Pay'!G141/1000 -> 21486.155 | L9: =D9-E9 -> 0 | M9: =G9-H9 -> 0 | N9: =J9-K9 -> 53513.845 | O9: 180000 | P9: =I9-O9 -> 120000 | Q9: =I9-16919.344 -> 283080.66
A10: 6 | B10: 14, भाडेपट्टी व कर | C10: 14000 | D10: 0 | E10: 0 | F10: 6000 | G10: 0 | H10: 0 | I10: 50000 | J10: 5000 | K10: ='BILLS 27 For Pay'!G142/1000 -> 4779 | L10: =D10-E10 -> 0 | M10: =G10-H10 -> 0 | N10: =J10-K10 -> 221
A11: 7 | B11: 16, प्रकाशने | C11: 1 | D11: 0 | E11: 0 | F11: 1 | G11: 0 | H11: 0 | I11: 1 | L11: =D11-E11 -> 0 | M11: =G11-H11 -> 0 | N11: =J11-K11 -> 0
A12: 8 | B12: 17, संगणक खर्च | C12: 35000 | D12: 0 | E12: 0 | F12: 15000 | G12: 0 | H12: 0 | I12: 600000 | J12: 150000 | K12: ='BILLS 27 For Pay'!G144/1000 -> 4701.346 | L12: =D12-E12 -> 0 | M12: =G12-H12 -> 0 | N12: =J12-K12 -> 145298.65 | O12: =I12-J12 -> 450000 | P12: =I12-O12 -> 150000 | Q12: =I12-2500 -> 597500
A13: 9 | B13: 21, पुरवठा व सामुग्री | C13: 1 | D13: 0 | E13: 0 | F13: 1 | G13: 0 | H13: 0 | I13: 10000 | L13: =D13-E13 -> 0 | M13: =G13-H13 -> 0 | N13: =J13-K13 -> 0
A14: 10 | B14: 24, पेट्रोल, तेल व वंगण | C14: 1 | D14: 0 | E14: 0 | F14: 1 | G14: 0 | H14: 0 | I14: 5000 | L14: =D14-E14 -> 0 | M14: =G14-H14 -> 0 | N14: =J14-K14 -> 0
A15: 11 | B15: 26, जाहीरात व प्रसिध्दी | C15: 58800 | D15: 1000 | E15: 0 | F15: 25200 | G15: 300 | H15: 0 | I15: 60000 | J15: 15000 | K15: ='BILLS 27 For Pay'!G147/1000 -> 500 | L15: =D15-E15 -> 1000 | M15: =G15-H15 -> 300 | N15: =J15-K15 -> 14500
A16: 12 | B16: 27, लहान बांधकामे | C16: 1 | D16: 0 | E16: 0 | F16: 1 | G16: 0 | H16: 0 | I16: 244999 | J16: 20000 | K16: ='BILLS 27 For Pay'!H148/1000 -> 0 | L16: =D16-E16 -> 0 | M16: =G16-H16 -> 0 | N16: =J16-K16 -> 20000 | O16: 230000 | P16: =I16-O16 -> 14999
A17: 13 | B17: 28, व्यावसायिक सेवा | C17: 110800 | D17: 0 | E17: 0 | F17: 47500 | G17: 0 | H17: 0 | I17: 80000 | L17: =D17-E17 -> 0 | M17: =G17-H17 -> 0 | N17: =J17-K17 -> 0
A18: 14 | B18: 31, सहाय्यक अनुदान (वेतनेतर) | C18: 7000 | D18: 0 | E18: 0 | F18: 3000 | G18: 0 | H18: 0 | I18: 550000 | J18: 350000 | K18: ='BILLS 27 For Pay'!G150/1000 -> 349600 | L18: =D18-E18 -> 0 | M18: =G18-H18 -> 0 | N18: =J18-K18 -> 400 | Q18: =I18-K18 -> 200400
B19: एकूण | C19: =SUM(C5:C18) -> 756704 | D19: =SUM(D5:D18) -> 190664 | E19: =SUM(E5:E18) -> 160192.28 | F19: =SUM(F5:F18) -> 341324 | G19: =SUM(G5:G18) -> 67300 | H19: =SUM(H5:H18) -> 51054.461 | I19: =SUM(I5:I18) -> 2190000 | J19: =SUM(J5:J18) -> 670000 | K19: =SUM(K5:K18) -> 431610.47 | L19: =D19-E19 -> 30471.723 | M19: =G19-H19 -> 16245.539 | N19: =J19-K19 -> 238389.53 | O19: =SUM(O5:O18) -> 860000 | P19: =I19-O19 -> 1330000

Sheet BILLS 2027
A1: Bills as on 10/06/2026 – MahaSTRIDE Operation | L1: 3451A215 | N1: 3451A224 | P1: 3451A233
A2: Sr.No. | B2: Particulars | C2: Invoice No. | D2: Invoice Date | E2: Billing Month | F2: Bill Received Date | G2: Received Bills amount Rs | H2: Status | I2: Aproved Bills-for-- Treasury | J2: Order Date | K2: Remarks, if any | L2: 10 Cont Services | M2: 26 Advertise | N2: 10 Cont Services | O2: 26 Advertise | P2: 06 Telephone | Q2: 10 Cont Services | R2: 13 Office Exp | S2: 14 Rent | T2: 17 Computer | U2: 26 Advertise | V2: 27 Minor Works | W2: 28 Prof Services | X2: 31 Graint in Aid
A3: 1 | B3: PMC - KPMG Advisory Services Pvt. Ltd. 3062986 | C3: KASP-MH/900033 | D3: 28/04/2025 | E3: 46082 | G3: 1877746 | I3: =341386+1453760 -> 1795146 | J3: 23.02.2026 | K3: Monthly Progress Report Approved.
C4: KASP-MH/100069 | D4: 25/05/2026 | E4: 10% Deliverable | G4: 3657952
C5: KASP-MH/A100127 | D5: 46184 | E5: NOV. 2025 to Feb 2026
B6: 3451A215 | E6: TOTAL-A | G6: =G3+G4 -> 5535698
A8: 2 | B8: District Strategic Unit (DSU) | C8: 3451A215 10-Cont Services
B9: Division : DSU Nashik - KPMG Advisory 3076998 | C9: KASP-HR/900709 | D9: 46171 | E9: 46023 | F9: 29.05.2026 | G9: 4633825 | K9: Substitution of the staff has been approved by IBRD/World Bank, and the contract amendment is in process.
C10: KASP-HR/A100228 | D10: 31/05/2026 | E10: 46054 | F10: 02.06.2026 | G10: 5067348
C11: KASP-HR/A100218 | D11: 31/05/2026 | E11: 46082 | F11: 02.06.2026 | G11: 5158115
C12: KASP-HR/A100218 | D12: 31/05/2026 | E12: 46113
B13: 3451A215 | E13: TOTAL-B | G13: =SUM(G9:G11) -> 14859288
A15: 3 | B15: Division : Pune - STC 3076970 | C15: MahaSTRIDE/DSU/Pune/005 | D15: 46099 | E15: Oct.2025 | G15: 2512984 | K15: Substitution of the staff has been approved by IBRD/World Bank, and the contract amendment is in process.
C16: MahaSTRIDE/DSU/Pune/006 | D16: 46099 | E16: Nov.2025 | G16: 2760750
C17: MahaSTRIDE/DSU/Pune/007 | D17: 46099 | E17: Dec.2025 | G17: 2681371
C18: MahaSTRIDE/8 | D18: 46150 | E18: 46023 | G18: 2610484
C19: MahaSTRIDE/9 | D19: 46150 | E19: 46054 | G19: 2475000
B20: 3451A215 | E20: TOTAL-C | G20: =SUM(G15:G19) -> 13040589
A22: 4 | B22: Division : CSN- Choice Consultancy 3081210 | C22: CCS/25-26/02-75 | D22: 16/02/2026 | E22: 46023 | G22: 5782137 | K22: The MPR with attendance has not been attached.
C23: CCS/25-26/03-84 | D23: 16/03/2026 | E23: 46054 | G23: 4757544
C24: CCS/25-26/04-47 | D24: 23/04/2026 | E24: 46082 | G24: 3537097
B25: 3451A215 | E25: TOTAL-E | G25: =SUM(G22:G24) -> 14076778
A26: 5 | B26: Division : Amravati - Limpico & Co. | C26: 40/2025-26 | D26: 18-03-2026 | E26: 46023 | G26: 1405176 | H26: ISSUED | I26: 482279 | J26: 23.03.2026 | K26: Substitution of the staff has been approved by IBRD/World Bank, and the contract amendment is in process.
C27: 42/2025-26 | D27: 27-03-2026 | E27: 46054 | G27: 1602686
C28: 42/2025-26 | D28: 27-03-2026 | E28: 46082 | G28: 1552946
C29: 42/2025-26 | D29: 27-03-2026 | E29: 46113 | G29: 1625749
B30: 3451A215 | E30: TOTAL-F | G30: =SUM(G26:G29) -> 6186557
A31: 6 | B31: Division: Nagpur - E & Y LLP | C31: IN91HR6L029540 | D31: 46055 | E31: 45839 | G31: 840952.71 | H31: ISSUED | I31: 840952.71 | J31: 21.04.2026 | L31: 840952.71
C32: IN91HR6L029397 | D32: 46055 | E32: 45870 | G32: 2215560.4 | H32: ISSUED | I32: 2215560.4 | J32: 21.04.2026 | K32: Pending Bills | L32: 2215560.4
C33: IN91HR6L029396 | D33: 46055 | E33: Sept.25 | G33: 4084337 | H33: ISSUED | I33: 4084337 | J33: 21.04.2026 | L33: 4084337
C34: IN91HR6L030924 | D34: 46070 | E34: Oct.2025 | G34: 5703517 | H34: ISSUED | I34: 5703517 | J34: 21.04.2026 | L34: 5703517
C35: IN91HR6L030925 | D35: 46070 | E35: Nov.2025 | G35: 5685511 | H35: ISSUED | I35: 5668850 | J35: 21.04.2026 | L35: 5668850
C36: IN91HR6L030926 | D36: 46070 | E36: Dec.2025 | G36: 5687393 | H36: ISSUED | I36: 5687393 | J36: 21.04.2026 | L36: 5687393
C37: IN91HR6L030927 | D37: 46070 | E37: Jan.2026 | G37: 5711580 | H37: ISSUED | I37: 5711580 | J37: 21.04.2026 | L37: 5711580
E38: Sub-total F | G38: =SUM(G31:G37) -> 29928851 | I38: =SUM(I31:I37) -> 29912190
B39: 3451A224 | C39: IN91HR7L033250 | D39: 11.03.2026 | E39: Feb.2026 | G39: 5734901 | H39: RECEIVED | I39: 5734901 | J39: 05.05.2026
C40: IN91HR7L003872 | D40: 14.05.2026 | E40: Mar.2026 | G40: 5727703 | H40: RECEIVED | I40: 5727703 | J40: 05.06.2026
C41: IN91HR7L004147 | D41: 19.05.2026 | E41: 12%Milestone Based | G41: 11028148 | H41: RECEIVED | I41: 11028148 | J41: 05.06.2026
C42: IN91HR7L004148 | D42: 19.05.2026 | E42: 5%Deliverable Based | G42: 4595062
C43: IN91HR7L005348 | D43: 03.06.2026 | E43: 4%Half yearly | F43: 24.06.2026 | H43: 24.06.2026 | I43: 3676049
...

Sheet Minutes BILLS 16.3.2026
A1: Minutes of Meeting of bill committee for PMC and District Strategic Unit (DSU) bills – MahaSTRIDE Operation Dt 16.03.2026
A2: Sr.No. | B2: Particulars | C2: Inv. No. | D2: Date | E2: Billing Month | F2: Received Bills | G2: Checked Amount | H2: Remarks, if any | I2: Remark
A3: 1 | B3: PMC - KPMG Advisory Services Pvt. Ltd. 3062986 | C3: KASP-MH/900741 | D3: 16.02.2026 | E3: Nov.2025 | F3: 1877746 | G3: 1877746 | I3: PMC(KPMG) Bills of month Nov 2025 to Feb 2026 for amount INR 7510948/- have been reviewed and approved by the committee.
C4: KASP-MH/900745 | D4: 17.02.2026 | E4: Dec.2025 | F4: 1877746 | G4: 1877746
C5: KASP-MH/900759 | D5: 20.02.2026 | E5: Jan.2026 | F5: 1877746 | G5: 1877746
C6: KASP-MH/900806 | D6: 28.02.2026 | E6: Feb.2026 | F6: 1877746 | G6: 1877746
E7: Total A | F7: =SUM(F3:F6) -> 7510984 | G7: =SUM(G3:G6) -> 7510984
A8: 2 | B8: DSU Division : Nashik - KPMG Advisory 3076998 | C8: KASP-HR/901275 | D8: 28.01.2026 | E8: Oct.2025 | F8: 4005406 | G8: 4005406 | I8: KPMG Nashik Bills of month Oct 2025 to Dec 2025 for amount INR 12778617/- have been reviewed and approved by the committee.
C9: KASP-HR/901277 | D9: 28.01.2026 | E9: Nov.2025 | F9: 4246022 | G9: 4246022
C10: KASP-HR/901289 | D10: 31.01.2026 | E10: Dec.2025 | F10: 4527189 | G10: 4527189
E11: Sub-total B | F11: =SUM(F8:F10) -> 12778617 | G11: =SUM(G8:G10) -> 12778617
A12: 3 | B12: DSU Division : Chhatrapati Sambhaji Nagar- Choice Consultancy | C12: CCSPT/25-26/07-01 | D12: 25/07/2025 | E12: 45833 | F12: 2787500 | G12: 2787500 | H12: The MPR with attendance has not been attached. | I12: Choice Consultancy Nashik Bills of month Jun 2025 to Dec 2025 for amount INR 38974760/- have been reviewed and approved by the committee.
C13: CCS/25-26/08-04 | D13: 45969 | E13: 45863 | F13: 5419597 | G13: 5419597 | H13: The foreclosure process is ongoing.
C14: CCS/25-26/09-25 | D14: 16/09/2025 | E14: 45870 | F14: 6104879 | G14: 6104879
C15: CCS/25-26/10-13 | D15: 13/10/2025 | E15: Sept.25 | F15: 6540000 | G15: 6540000
C16: CCS/25-26/11-43 | D16: 13/11/2025 | E16: Oct.2025 | F16: 6541331 | G16: 6541331
C17: CCS/25-26/01-39 | D17: 22/01/2026 | E17: Nov.2025 | F17: 5797501 | G17: 5797501
C18: CCS/25-26/01-40 | D18: 22/01/2026 | E18: Dec.2025 | F18: 5783952 | G18: 5783952
E19: Sub-total D | F19: =SUM(F12:F18) -> 38974760 | G19: =SUM(G12:G18) -> 38974760
A20: 4 | B20: DSU Division : Amravati - Linpico & Co. | C20: 10-2025-26 | D20: 45901 | E20: 45809 | F20: 525724 | G20: 482279 | H20: Substitution of the staff has been approved by IBRD/World Bank, and the contract amendment is in process. | I20: Linpico and Co. Amaravati Bills of month Jun 2025 to Dec 2025 for ramount INR 8212073/- have been reviewed and approved by the committee with recalculated amount of the month Oct and Nov 2025.
C21: 11/2025-26 | D21: 45901 | E21: 45839 | F21: 1190856 | G21: 1167424
C22: 16/2025-26 | D22: 45922 | E22: 45870 | F22: 1350611 | G22: 1350611
C23: 21/2025-26 | D23: 45981 | E23: Sept-.2025 | F23: 1671415 | G23: 1671415
C24: 31/2025-26 | D24: 46038 | E24: Oct & Nov 25 | F24: 2628416 | G24: 2520186
C25: 35/2025-26 | D25: 46057 | E25: 45992 | F25: 1028564 | G25: 1020158
E26: Sub-total E | F26: =SUM(F20:F25) -> 8395586 | G26: =SUM(G20:G25) -> 8212073
A27: 5 | B27: DSU Division: Nagpur - E & Y LLP | C27: IN91HR6L029540 | D27: 46055 | E27: 45863 | F27: 840952.71 | G27: 840952.71 | I27: E&Y LLP Nagpur Bills of month Jul 2025 to Jan 2026 for ramount INR 2,99,12,190/- have been reviewed and approved by the committee with recalculated amount of the month Nov 2025.
C28: IN91HR6L029397 | D28: 46055 | E28: 45894 | F28: 2215560.4 | G28: 2215560.4 | H28: Pending Bills
C29: IN91HR6L029396 | D29: 46055 | E29: Sept.25 | F29: 4084337 | G29: 4084337
C30: IN91HR6L030924 | D30: 46070 | E30: Oct.2025 | F30: 5703517 | G30: 5703517
C31: IN91HR6L030925 | D31: 46070 | E31: Nov.2025 | F31: 5685511 | G31: 5668850
C32: IN91HR6L030926 | D32: 46070 | E32: Dec.2025 | F32: 5687393 | G32: 5687393
C33: IN91HR6L030927 | D33: 46070 | E33: 46023 | F33: 5711580 | G33: 5711580
E34: Sub-total F | F34: =SUM(F27:F33) -> 29928851 | G34: =SUM(G27:G33) -> 29912190
C35: IPF- 3451A215 | E35: 10 Cont Services | F35: =F7+F11+F19+F26+F34 -> 97588798 | G35: =G7+G11+G19+G26+G34 -> 97388624
A36: 6 | B36: Director of Economics and Statistics for Training and tablets | C36: training 3451A233 | D36: 09.03.2026 | E36: 13 Office Exp | F36: 1060000 | G36: 1060000 | I36: Bills other than DSU and PMC can be submitted as routin work instead of go to Bill committee, While such bills amounting above INR 1.00 cr should brought to Bill committee.
C37: tablets 3451A233 | D37: 09.03.2026 | E37: 17 COMPUTER | F37: 6722000 | G37: 6722000
A38: 7 | B38: ADVERTISE by DES for PMC appoint | C38: 3451A233 | D38: 23.02.2026 | E38: 13 Office Exp | F38: 105125 | G38: 105125
A39: 8 | B39: Payment to MRSAC for purchase Computer software | C39: 3451A233 | D39: 17.02.2026 | E39: 17 COMPUTER | F39: 116820000 | G39: 116820000
A40: 9 | B40: Mr. Somnath Shambhunaths Travel invoice | C40: 3451A215 | D40: 16.09.2025 | E40: 13 Office Exp | F40: 8470 | G40: 8470 | I40: Bill is approved to pay from MITRAS Head 3451A126 as that expert is not appointed on MahaSTRIDE Project.

Sheet BILLS 16.3.2026
A1: Status of pending bills as on 13/03/2026 – MahaSTRIDE Operation
A2: Sr.No. | B2: Particulars | C2: Inv. No. | D2: Date | E2: Billing Month | F2: Received Bills | G2: Checked Amount | H2: Remarks, if any | I2: Remark
A3: 1 | B3: PMC - KPMG Advisory Services Pvt. Ltd. 3062986 | C3: KASP-MH/900741 | D3: 16.02.2026 | E3: Nov.2025 | F3: 1877746 | G3: 1877746
C4: KASP-MH/900745 | D4: 17.02.2026 | E4: Dec.2025 | F4: 1877746 | G4: 1877746
C5: KASP-MH/900759 | D5: 20.02.2026 | E5: Jan.2026 | F5: 1877746 | G5: 1877746
C6: KASP-MH/900806 | D6: 28.02.2026 | E6: Feb.2026 | F6: 1877746 | G6: 1877746
E7: Total A | F7: =SUM(F3:F6) -> 7510984 | G7: =SUM(G3:G6) -> 7510984
A8: 2 | B8: District Strategic Unit (DSU)
B9: Division : Nashik - KPMG Advisory 3076998 | C9: KASP-HR/901275 | D9: 28.01.2026 | E9: Oct.2025 | F9: 4005406 | G9: 4005406
C10: KASP-HR/901277 | D10: 28.01.2026 | E10: Nov.2025 | F10: 4246022 | G10: 4246022
C11: KASP-HR/901289 | D11: 31.01.2026 | E11: Dec.2025 | F11: 4527189 | G11: 4527189
E12: Sub-total B | F12: =SUM(F9:F11) -> 12778617 | G12: =SUM(G9:G11) -> 12778617
A13: 3 | B13: Division : Chhatrapati Sambhaji Nagar- Choice Consultancy | C13: CCSPT/25-26/07-01 | D13: 25/07/2025 | E13: 45833 | F13: 2787500 | G13: 2787500 | H13: The MPR with attendance has not been attached.
C14: CCS/25-26/08-04 | D14: 45969 | E14: 45863 | F14: 5419597 | G14: 5419597 | H14: The foreclosure process is ongoing.
C15: CCS/25-26/09-25 | D15: 16/09/2025 | E15: 45870 | F15: 6104879 | G15: 6104879
C16: CCS/25-26/10-13 | D16: 13/10/2025 | E16: Sept.25 | F16: 6540000 | G16: 6540000
C17: CCS/25-26/11-43 | D17: 13/11/2025 | E17: Oct.2025 | F17: 6541331 | G17: 6541331
C18: CCS/25-26/01-39 | D18: 22/01/2026 | E18: Nov.2025 | F18: 5797501 | G18: 5797501
C19: CCS/25-26/01-40 | D19: 22/01/2026 | E19: Dec.2025 | F19: 5783952 | G19: 5783952
E20: Sub-total D | F20: =SUM(F13:F19) -> 38974760 | G20: =SUM(G13:G19) -> 38974760
A21: 4 | B21: Division : Amravati - Limpico & Co. | C21: 10-2025-26 | D21: 45901 | E21: 45809 | F21: 525724 | G21: 482279 | H21: Substitution of the staff has been approved by IBRD/World Bank, and the contract amendment is in process.
C22: 11/2025-26 | D22: 45901 | E22: 45839 | F22: 1190856 | G22: 1167424
C23: 16/2025-26 | D23: 45922 | E23: 45870 | F23: 1350611 | G23: 1350611
C24: 21/2025-26 | D24: 45981 | E24: Sept-.2025 | F24: 1671415 | G24: 1671415
C25: 31/2025-26 | D25: 46038 | E25: Oct & Nov 25 | F25: 2628416 | G25: 2520186
C26: 35/2025-26 | D26: 46057 | E26: 45992 | F26: 1028564 | G26: 1020158
E27: Sub-total E | F27: =SUM(F21:F26) -> 8395586 | G27: =SUM(G21:G26) -> 8212073
A28: 5 | B28: Division: Nagpur - E & Y LLP | C28: IN91HR6L029540 | D28: 46055 | E28: 45863 | F28: 840952.71 | G28: 840952.71
C29: IN91HR6L029397 | D29: 46055 | E29: 45894 | F29: 2215560.4 | G29: 2215560.4 | H29: Pending Bills
C30: IN91HR6L029396 | D30: 46055 | E30: Sept.25 | F30: 4084337 | G30: 4084337
C31: IN91HR6L030924 | D31: 46070 | E31: Oct.2025 | F31: 5703517 | G31: 5703517
C32: IN91HR6L030925 | D32: 46070 | E32: Nov.2025 | F32: 5685511 | G32: 5668850
C33: IN91HR6L030926 | D33: 46070 | E33: Dec.2025 | F33: 5687393 | G33: 5687393
C34: IN91HR6L030927 | D34: 46070 | E34: 46023 | F34: 5711580 | G34: 5711580
E35: Sub-total F | F35: =SUM(F28:F34) -> 29928851 | G35: =SUM(G28:G34) -> 29912190
C36: IPF- 3451A215 | E36: 10 Cont Services | F36: =F7+F12+F20+F27+F35 -> 97588798 | G36: =G7+G12+G20+G27+G35 -> 97388624
A37: 6 | B37: Director of Economics and Statistics for Training and tablets | C37: training 3451A233 | D37: 09.03.2026 | E37: 13 Office Exp | F37: 1060000 | G37: 1060000
C38: tablets 3451A233 | D38: 09.03.2026 | E38: 17 COMPUTER | F38: 6722000 | G38: 6722000
A39: 7 | B39: ADVERTISE by DES for PMC appoint | C39: 3451A233 | D39: 23.02.2026 | E39: 13 Office Exp | F39: 105125 | G39: 105125
A40: 8 | B40: Mr. Somnath Shambhunaths Travel invoice | C40: 3451A215 | D40: 16.09.2025 | E40: 13 Office Exp | F40: 8470 | G40: 8470 | I40: MITRA
...

Sheet Pending Bills- MahaSTRIDE
A1: Status of Approved and pending bills as on 05/02/2026 – MahaSTRIDE Operation
A2: Sr.No. | B2: Particulars | C2: Inv. No. | D2: Date | E2: Billing Month | F2: Approved Bills | G2: Pending Bills | H2: Remarks, if any
